<?xml version="1.0" encoding="utf-8"?>

<!-- 
    This URDF uses the Denavit-Hartenberg (DH) conventions to place the reference frames of the joints.
    It uses offsets to correctly place the visual and collision meshes. 
-->

<robot  name="fanuc"  xmlns:xacro="http://www.ros.org/wiki/xacro">         
    
    <!-- ******************** Used for fixing robot to Gazebo 'base_link' ********************-->
    <link name="world"/>

    <joint name="virtual_joint" type="fixed">
        <parent link="world"/>
        <child link="base_link"/>
    </joint>
    
    
    <!--************************************************BASE_LINK********************************************-->
    <link name="base_link">
        <visual>
            <origin xyz="0 0 0" rpy="0 0 0" />
            <geometry>
                <mesh filename="package://fanuc_description/meshes/visual/link_0.dae" />
            </geometry>
            <material name=""/>
        </visual>

        <collision>
            <origin xyz="0 0 0" rpy="0 0 0" />
            <geometry>
                <mesh filename="package://fanuc_description/meshes/collision/link_0.stl" />
            </geometry>
        </collision>

    </link>


    <!--************************************************LINK 1********************************************-->
    <link name="link1">
        <visual>
            <origin xyz="0 0 0" rpy="0 0 0" />
            <geometry>
                <mesh filename="package://fanuc_description/meshes/visual/link_1.dae" />
            </geometry>
            <material name=""/>
        </visual>

        <collision>
            <origin xyz="0 0 0" rpy="0 0 0" />
            <geometry>
                <mesh filename="package://fanuc_description/meshes/collision/link_1.stl" />
            </geometry>
        </collision>

    </link>

    <joint name="joint1" type="revolute">
        <!--Joint properties-->
        <origin xyz="0 0 0" rpy="0 0 0" />
        <parent link="base_link" />
        <child link="link1" />
        <axis xyz="0 0 1" />
        <limit lower="-2.967" upper="2.967" effort="12" velocity="2.443" />
    </joint>


     <!--************************************************LINK 2********************************************-->
    <link name="link2">
        <visual>
            <origin xyz="-0.150 0.525 0" rpy="1.5708 0 0" />
            <geometry>
                <mesh filename="package://fanuc_description/meshes/visual/link_2.dae" />
            </geometry>
            <material name=""/>
        </visual>

        <collision>
            <origin xyz="-0.150 0.525 0" rpy="1.5708 0 0" />
            <geometry>
                <mesh filename="package://fanuc_description/meshes/collision/link_2.stl" />
            </geometry>
        </collision>

    </link>

    <joint name="joint2" type="revolute">
        <!--Joint properties-->
        <origin xyz="0.15 0 0.52" rpy="-1.5708 0 0" />
        <parent link="link1" />
        <child link="link2" />
        <axis xyz="0 0 1" />
        <limit lower="-1.4835" upper="2.7052" effort="12" velocity="2.792" />
    </joint>


    <!--************************************************LINK 3********************************************-->
    <link name="link3">
        <visual>
            <origin xyz="1.465 0.15 0.15" rpy="-1.5708 1.5708 1.5708" />
            <geometry>
                <mesh filename="package://fanuc_description/meshes/visual/link_3.dae" />
            </geometry>
             <material name=""/>
        </visual>

        <collision>
            <origin xyz="1.465 0.15 0.15" rpy="-1.5708 1.5708 1.5708" />
            <geometry>
                <mesh filename="package://fanuc_description/meshes/collision/link_3.stl" />
            </geometry>
        </collision>

    </link>

    <joint name="joint3" type="revolute">
        <!--Joint properties-->
        <origin xyz="0 -0.79 0" rpy="0 0 -1.5708" />
        <parent link="link2" />
        <child link="link3" />
        <axis xyz="0 0 1" />
        <limit lower="-1.5707" upper="1.3962" effort="12" velocity="2.967" />
    </joint>


     <!--************************************************LINK 4********************************************-->
    <link name="link4">
        <!--Link properties-->
        <visual>
            <origin xyz="1.465 0 -0.150" rpy="0 -1.5708 0" />
            <geometry>
                <mesh filename="package://fanuc_description/meshes/visual/link_4.dae" />
            </geometry>
            <material name=""/>
        </visual>

        <collision>
            <origin xyz="0 -1.450  1.200" rpy="0 1.5708 1.5708" />
            <geometry>
                <mesh filename="package://fanuc_description/meshes/collision/link_4.stl" />
            </geometry>
        </collision>

    </link>

    <joint name="joint4" type="revolute">
        <!--Joint properties-->
        <origin xyz="0.15 0 0" rpy="-1.5708 0 0" />
        <parent link="link3" />
        <child link="link4" />
        <axis xyz="0 0 1" />
        <limit lower="-3.6651" upper="3.6651" effort="11.7" velocity="10.47" />
    </joint>


    <!--************************************************LINK 5********************************************-->
    <link name="link5">

        <visual>
            <origin xyz="1.465 -1.010 0" rpy="-1.5708 0 1.5708" />
            <geometry>
                <mesh filename="package://fanuc_description/meshes/visual/link_5.dae" />
            </geometry>
            <material name=""/>
        </visual>

        <collision>
            <origin xyz="1.465 -1.010 0" rpy="-1.5708 0 1.5708" />
            <geometry>
                <mesh filename="package://fanuc_description/meshes/collision/link_5.stl" />
            </geometry>
        </collision>

    </link>
    
    <joint name="joint5" type="revolute">
        <!--Joint properties-->
        <origin xyz="0 0 0.860" rpy="1.5708 0 0" />
        <parent link="link4" />
        <child link="link5" />
        <axis xyz="0 0 1" />
        <limit lower="-2.2689" upper="2.2689" effort="11.7" velocity="6.545" />
    </joint>


    <!--************************************************LINK 6********************************************-->
    <link name="link6">

        <visual>
            <origin xyz="0 0 0" rpy="0 0 0" />
            <geometry>
                <mesh filename="package://fanuc_description/meshes/visual/link_6.dae" />
            </geometry>
            <material name=""/>
        </visual>

        <collision>
            <origin xyz="0 0 0" rpy="0 0 0" />
            <geometry>
                <mesh filename="package://fanuc_description/meshes/collision/link_6.stl" />
            </geometry>
        </collision>

    </link>

    <joint name="joint6" type="revolute">
        <!--Joint properties-->
        <origin xyz="0 0 0" rpy="-1.5708 0 0" />
        <parent link="link5" />
        <child link="link6" />
        <axis xyz="0 0 1" />
        <limit lower="-47.1238" upper="47.1238" effort="5.8" velocity="9.6" />
    </joint>

    <!--************************************************FLANGE********************************************-->
    <link name="flange"/>

    <joint name="flange" type="fixed">
        <!--Joint properties-->
        <origin xyz="0 0 0.100" rpy="0 0 0" />
        <parent link="link6" />
        <child link="flange" />
    </joint>

</robot>
